<?xml version='1.0'?>
<robot name="tricycle">
  <material name="grey">
    <color rgba="0.8 0.8 0.8 1"/>
  </material>
  <material name="white">
    <color rgba="1 1 1 1 "/>
  </material>
  <link name='base_link'>
    <visual>
      <geometry>
        <box size=".4 .2 .1"/>
      </geometry>
      <origin rpy="0 0 0" xyz="0 0 0.1"/>
      <material name="white"/>
    </visual>
    <collision>
      <origin rpy="0 0 0" xyz="0 0 0.1"/>
      <geometry>
        <box size=".4 .2 .1"/>
      </geometry>
    </collision>
    <inertial>
      <origin rpy="0 0 0" xyz="0 0 0.1"/>
      <mass value="1"/>
      <inertia ixx="1" ixy="0" ixz="0" iyy="1" iyz="0" izz="1"/>
    </inertial>
  </link>

  <link name="front_wheel">
    <visual>
      <geometry>
        <cylinder length=".05" radius=".1"/>
      </geometry>
      <material name="grey"/>
    </visual>
    <collision>
      <geometry>
        <cylinder length=".05" radius=".1"/>
      </geometry>
    </collision>
    <inertial>
      <mass value="1"/>
      <inertia ixx="1" ixy="0" ixz="0" iyy="1" iyz="0" izz="1"/>
    </inertial>
  </link>
  <joint type="revolute" name="front_wheel_hinge">
    <origin rpy="0 -1.5707 1.5707" xyz="0.2 0 0.1"/>
    <child link="front_wheel"/>
    <parent link="base_link"/>
    <axis xyz="1 0 0"/>
    <limit effort="1000.0" lower="-1.0" upper="1.0" velocity="0.5"/>
  </joint>
  <transmission name="front_wheel_trans">
    <type>transmission_interface/SimpleTransmission</type>
    <actuator name="$front_wheel_motor">
      <mechanicalReduction>1</mechanicalReduction>
    </actuator>
    <joint name="front_wheel_hinge">
      <hardwareInterface>hardware_interface/PositionJointInterface
      </hardwareInterface>
    </joint>
  </transmission>
  <gazebo reference="front_wheel">
    <mu1 value="20.0"/>
    <mu2 value="10.0"/>
    <kp value="10000000.0"/>
    <kd value="1.0"/>
    <material>Gazebo/Grey</material>
  </gazebo>

  <link name="left_wheel">
    <visual>
      <geometry>
        <cylinder length=".05" radius=".1"/>
      </geometry>
      <material name="grey"/>
    </visual>
    <collision>
      <geometry>
        <cylinder length=".05" radius=".1"/>
      </geometry>
    </collision>
    <inertial>
      <mass value="1"/>
      <inertia ixx="1" ixy="0" ixz="0" iyy="1" iyz="0" izz="1"/>
    </inertial>
  </link>
  <joint type="revolute" name="left_wheel_hinge">
    <origin rpy="0 1.5707 1.5707" xyz="-0.1 0.13 0.1"/>
    <child link="left_wheel"/>
    <parent link="base_link"/>
    <axis xyz="0 0 1"/>
    <limit effort="1000.0" velocity="0.5" lower="0" upper="10"/>
  </joint>
  <transmission name="left_wheel_trans">
    <type>transmission_interface/SimpleTransmission</type>
    <actuator name="$left_wheel_motor">
      <mechanicalReduction>1</mechanicalReduction>
    </actuator>
    <joint name="left_wheel_hinge">
      <hardwareInterface>hardware_interface/VelocityJointInterface
      </hardwareInterface>
    </joint>
  </transmission>
  <gazebo reference="left_wheel">
    <mu1 value="20.0"/>
    <mu2 value="10.0"/>
    <kp value="10000000.0"/>
    <kd value="1.0"/>
    <material>Gazebo/Grey</material>
  </gazebo>

  <link name="right_wheel">
    <visual>
      <geometry>
        <cylinder length=".05" radius=".1"/>
      </geometry>
      <material name="grey"/>
    </visual>
    <collision>
      <geometry>
        <cylinder length=".05" radius=".1"/>
      </geometry>
    </collision>
    <inertial>
      <mass value="1"/>
      <inertia ixx="1" ixy="0" ixz="0" iyy="1" iyz="0" izz="1"/>
    </inertial>
  </link>
  <joint type="revolute" name="right_wheel_hinge">
    <origin rpy="0 1.5707 1.5707" xyz="-0.1 -0.13 0.1"/>
    <child link="right_wheel"/>
    <parent link="base_link"/>
    <axis xyz="0 0 1"/>
    <limit effort="1000.0" velocity="0.5" lower="0" upper="10"/>
  </joint>
  <transmission name="right_wheel_trans">
    <type>transmission_interface/SimpleTransmission</type>
    <actuator name="$right_wheel_motor">
      <mechanicalReduction>1</mechanicalReduction>
    </actuator>
    <joint name="right_wheel_hinge">
      <hardwareInterface>hardware_interface/VelocityJointInterface
      </hardwareInterface>
    </joint>
  </transmission>
  <gazebo reference="right_wheel">
    <mu1 value="20.0"/>
    <mu2 value="10.0"/>
    <kp value="10000000.0"/>
    <kd value="1.0"/>
    <material>Gazebo/Grey</material>
  </gazebo>

  <gazebo>
    <plugin name="gazebo_ros_control" filename="libgazebo_ros_control.so">
      <robotNamespace>/</robotNamespace>
    </plugin>
  </gazebo>

</robot>